<?xml version="1.0" ?>
<!-- =================================================================================== -->
<!-- |    This document was autogenerated by xacro from urdf/pexod.xacro               | -->
<!-- |    EDITING THIS FILE BY HAND IS NOT RECOMMENDED                                 | -->
<!-- =================================================================================== -->
<robot name="pexod" xmlns:xacro="http://www.ros.org/wiki/xacro">
  <!-- <xacro:include filename="$(find pexod_description)/urdf/pexod_control.xacro" /> -->
  <!-- MATERIALS -->
  <material name="Blue">
    <color rgba="0 0 1 1"/>
  </material>
  <material name="Red">
    <color rgba="1 0 0 1"/>
  </material>
  <material name="Green">
    <color rgba="0 1 0 1"/>
  </material>
  <material name="Yellow">
    <color rgba="1 1 0 1"/>
  </material>
  <material name="LightGrey">
    <color rgba="0.6 0.6 0.6 1.0"/>
  </material>
  <material name="LightBlue">
    <color rgba="0.7 0.4 1.0 1.0"/>
  </material>
  <material name="LightYellow">
    <color rgba="0.72 1. 0.54 1.0"/>
  </material>
  <!-- END OF MATERIALS -->
  <!-- XACRO MACROS FOR VISUALS AND COLLISIONS -->
  <!-- END OF XACRO MACROS -->
  <!-- TORSO -->
    <link name="base_link">
        <visual>
        <!-- Relative to world frame -->
        <origin rpy="0 0 0" xyz="0 0 0"/>
        <geometry>
            <sphere radius="0.05"/>
        </geometry>
        <material name="Blue"/>
        </visual>
        <inertial>
            <origin rpy="0 0 0" xyz="0 0 0"/>
            <mass value="0.1"/>
            <inertia ixx="0.00081" ixy="0" ixz="0" iyy="0.00081" iyz="0" izz="0.00006"/>
        </inertial>
    </link>

    <joint name="base_link0" type="continuous">
        <parent link="base_link"/>
        <child link="link0"/>
        <limit effort="30.0" velocity="7.0"/>
        <!-- Relative to world frame -->
        <origin rpy="0 0 0" xyz="0 0 0"/>
        <axis xyz="0 0 1"/>
        <dynamics damping="0.6" friction="0.6"/>
    </joint>
  
    <link name="link0">
        <visual>
        <!-- Relative to corresponding joint frame -->
        <origin rpy="0 1.57079 0" xyz="0.15 0 0"/>
        <geometry>
            <cylinder length="0.3" radius="0.05"/>
        </geometry>
        <material name="LightBlue"/>
        </visual>
        <inertial>
            <origin rpy="0 0 0" xyz="0 0 0"/>
            <mass value="0.1"/>
            <inertia ixx="0.00081" ixy="0" ixz="0" iyy="0.00081" iyz="0" izz="0.00006"/>
        </inertial>
    </link>
 
    <joint name="link0_link1" type="fixed">
        <parent link="link0"/>
        <child link="link1"/>
        <!-- Relative to prev joint frame -->
        <origin rpy="0 0 0" xyz="0.3 0.0 0"/>
        <axis xyz="0 0 1"/>
        <dynamics damping="0.6" friction="0.6"/>
    </joint>
  
    <link name="link1">
        <visual>
        <!-- Relative to corresponding joint frame -->
        <origin rpy="0 0 0" xyz="0 0 0"/>
        <geometry>
            <sphere radius="0.05"/>
        </geometry>
        <material name="LightBlue"/>
        </visual>
        <inertial>
            <origin rpy="0 0 0" xyz="0 0 0"/>
            <mass value="0.1"/>
            <inertia ixx="0.0001" ixy="0" ixz="0" iyy="0.0001" iyz="0" izz="0.0001"/>
        </inertial>
    </link>

    <joint name="link1_link2" type="revolute">
        <parent link="link1"/>
        <child link="link2"/>
        <limit effort="30.0" lower="-1.0472" upper="1.0472" velocity="7.0"/>
        <!-- Relative to parent frame -->
        <origin rpy="0 0 0" xyz="0.0 0.0 0"/>
        <axis xyz="0 0 1"/>
        <dynamics damping="0.6" friction="0.6"/>
    </joint>
  
    <link name="link2">
        <visual>
        <!-- Relative to corresponding joint frame -->
        <origin rpy="0 1.57079 0" xyz="0.15 0 0"/>
        <geometry>
            <cylinder length="0.3" radius="0.05"/>
        </geometry>
        <material name="LightBlue"/>
        </visual>
        <inertial>
            <origin rpy="0 1.57079 0" xyz="0.15 0 0"/>
            <mass value="0.1"/>
            <inertia ixx="0.00081" ixy="0" ixz="0" iyy="0.00081" iyz="0" izz="0.00006"/>
        </inertial>
    </link>

    <joint name="link2_link3" type="fixed">
        <parent link="link2"/>
        <child link="link3"/>
        <!-- Relative to parent frame -->
        <origin rpy="0 0 0" xyz="0.3 0.0 0"/>
        <axis xyz="0 0 1"/>
        <dynamics damping="0.6" friction="0.6"/>
    </joint>
  
    <link name="link3">
        <visual>
        <!-- Relative to corresponding joint frame -->
        <origin rpy="0 0 0" xyz="0 0 0"/>
        <geometry>
            <sphere radius="0.05"/>
        </geometry>
        <material name="LightBlue"/>
        </visual>
        <inertial>
            <origin rpy="0 0 0" xyz="0 0 0"/>
            <mass value="0.1"/>
            <inertia ixx="0.0001" ixy="0" ixz="0" iyy="0.0001" iyz="0" izz="0.0001"/>
        </inertial>
    </link>

    <joint name="link3_link4" type="revolute">
        <parent link="link3"/>
        <child link="link4"/>
        <limit effort="30.0" lower="-1.0472" upper="1.0472" velocity="7.0"/>
        <!-- Relative to parent frame -->
        <origin rpy="0 0 0" xyz="0.0 0.0 0"/>
        <axis xyz="0 0 1"/>
        <dynamics damping="0.6" friction="0.6"/>
    </joint>
  
    <link name="link4">
        <visual>
        <!-- Relative to corresponding joint frame -->
        <origin rpy="0 1.57079 0" xyz="0.15 0 0"/>
        <geometry>
            <cylinder length="0.3" radius="0.05"/>
        </geometry>
        <material name="LightBlue"/>
        </visual>
        <inertial>
           <origin rpy="0 1.57079 0" xyz="0.15 0 0"/>
            <mass value="0.1"/>
            <inertia ixx="0.00081" ixy="0" ixz="0" iyy="0.00081" iyz="0" izz="0.00006"/>
        </inertial>
    </link>

    <joint name="link4_link5" type="fixed">
        <parent link="link4"/>
        <child link="link5"/>
        <!-- Relative to parent frame -->
        <origin rpy="0 0 0" xyz="0.3 0.0 0"/>
        <axis xyz="0 0 1"/>
        <dynamics damping="0.6" friction="0.6"/>
    </joint>
  
    <link name="link5">
        <visual>
        <!-- Relative to corresponding joint frame -->
        <origin rpy="0 0 0" xyz="0 0 0"/>
        <geometry>
            <sphere radius="0.05"/>
        </geometry>
        <material name="LightBlue"/>
        </visual>
        <inertial>
            <origin rpy="0 0 0" xyz="0 0 0"/>
            <mass value="0.1"/>
            <inertia ixx="0.0001" ixy="0" ixz="0" iyy="0.0001" iyz="0" izz="0.0001"/>
        </inertial>
    </link>

    <joint name="link5_link6" type="revolute">
        <parent link="link5"/>
        <child link="link6"/>
        <limit effort="30.0" lower="-1.0472" upper="1.0472" velocity="7.0"/>
        <!-- Relative to parent frame -->
        <origin rpy="0 0 0" xyz="0.0 0.0 0"/>
        <axis xyz="0 0 1"/>
        <dynamics damping="0.6" friction="0.6"/>
    </joint>
  
    <link name="link6">
        <visual>
        <!-- Relative to corresponding joint frame -->
        <origin rpy="0 1.57079 0" xyz="0.15 0 0"/>
        <geometry>
            <cylinder length="0.3" radius="0.05"/>
        </geometry>
        <material name="LightBlue"/>
        </visual>
        <inertial>
            <origin rpy="0 1.57079 0" xyz="0.15 0 0"/>
            <mass value="0.1"/>
            <inertia ixx="0.00081" ixy="0" ixz="0" iyy="0.00081" iyz="0" izz="0.00006"/>
        </inertial>
    </link>

    <joint name="link6_link7" type="fixed">
        <parent link="link6"/>
        <child link="link7"/>
        <!-- Relative to parent frame -->
        <origin rpy="0 0 0" xyz="0.3 0.0 0"/>
        <axis xyz="0 0 1"/>
        <dynamics damping="0.6" friction="0.6"/>
    </joint>
  
    <link name="link7">
        <visual>
        <!-- Relative to corresponding joint frame -->
        <origin rpy="0 0 0" xyz="0 0 0"/>
        <geometry>
            <sphere radius="0.05"/>
        </geometry>
        <material name="LightBlue"/>
        </visual>
        <inertial>
            <origin rpy="0 0 0" xyz="0 0 0"/>
            <mass value="0.1"/>
            <inertia ixx="0.0001" ixy="0" ixz="0" iyy="0.0001" iyz="0" izz="0.0001"/>
        </inertial>
    </link>

    <joint name="link7_link8" type="revolute">
        <parent link="link7"/>
        <child link="link8"/>
        <limit effort="30.0" lower="-1.0472" upper="1.0472" velocity="7.0"/>
        <!-- Relative to parent frame -->
        <origin rpy="0 0 0" xyz="0.0 0.0 0"/>
        <axis xyz="0 0 1"/>
        <dynamics damping="0.6" friction="0.6"/>
    </joint>
  
    <link name="link8">
        <visual>
        <!-- Relative to corresponding joint frame -->
        <origin rpy="0 1.57079 0" xyz="0.15 0 0"/>
        <geometry>
            <cylinder length="0.3" radius="0.05"/>
        </geometry>
        <material name="LightBlue"/>
        </visual>
        <inertial>
            <origin rpy="0 1.57079 0" xyz="0.15 0 0"/>
            <mass value="0.1"/>
            <inertia ixx="0.00081" ixy="0" ixz="0" iyy="0.00081" iyz="0" izz="0.00006"/>
        </inertial>
    </link>

    <joint name="link8_fingertip" type="fixed">
        <parent link="link8"/>
        <child link="fingertip"/>
        <!-- Relative to parent frame -->
        <origin rpy="0 0 0" xyz="0.3 0.0 0"/>
        <axis xyz="0 0 1"/>
        <dynamics damping="0.6" friction="0.6"/>
    </joint>
  
    <link name="fingertip">
        <visual>
        <!-- Relative to corresponding joint frame -->
        <origin rpy="0 0 0" xyz="0 0 0"/>
        <geometry>
            <sphere radius="0.05"/>
        </geometry>
        <material name="LightYellow"/>
        </visual>
        <inertial>
            <origin rpy="0 0 0" xyz="0 0 0"/>
            <mass value="0.1"/>
            <inertia ixx="0.0001" ixy="0" ixz="0" iyy="0.0001" iyz="0" izz="0.0001"/>
        </inertial>
    </link>

  <!-- END OF LEG LINKS/JOINTS -->
</robot>

